Workbook
Name Finanzas: CatModulo!$B$2:$B$8
Name Fiscal: CatModulo!$C$2:$C$4
Name Impacto: CatModulo!$J$2:$J$4
Name Modulo: CatModulo!$A$2:$A$4
Name Probabilidad: CatModulo!$K$2:$K$4
Name Tipo: CatModulo!$L$1:$L$5
Name Utilerias: CatModulo!$D$2:$D$4

Sheet Dashboard
A1: 📊 DASHBOARD DE AVANCE DE PRUEBAS - PORTAL DE PROVEEDORES FBC
A3: RESUMEN EJECUTIVO
A5: Total Escenarios | B5: ✅ Pasó | C5: ❌ Falló | D5: 🔄 En Progreso | E5: ⏳ Pendiente | F5: 🚫 Bloqueado | G5: 🐛 Con Bug Jira | H5: % Avance (Pasó) | I5: % Abiertos/Fallidos | K5: ⚠️ ESCENARIOS FALLIDOS O BLOQUEADO
K6: =_xlfn.CONCAT("Total: ",(COUNTIF('Matriz de Pruebas'!F3:F989,"Falló")+COUNTIF('Matriz de Pruebas'!F3:F989,"Bloqueado"))," de ",COUNTA('Matriz de Pruebas'!F3:F989," escenarios")) -> Total: 2 de 709
A7: =COUNTA('Matriz de Pruebas'!F3:F989) -> 708 | B7: =COUNTIF('Matriz de Pruebas'!F3:F989,"Pasó") -> 266 | C7: =COUNTIF('Matriz de Pruebas'!F3:F989,"Falló") -> 2 | D7: =COUNTIF('Matriz de Pruebas'!F3:F989,"En Progreso") -> 1 | E7: =COUNTIF('Matriz de Pruebas'!F3:F989,"Pendiente") -> 439 | F7: =COUNTIF('Matriz de Pruebas'!F3:F989,"Bloqueado") -> 0 | G7: =COUNTIF('Matriz de Pruebas'!I3:I989,"*") -> 2 | H7: =IFERROR(COUNTIF('Matriz de Pruebas'!F3:F989,"Pasó")/COUNTA('Matriz de Pruebas'!F3:F989),0) -> 0.37570621 | I7: =IFERROR((COUNTIF('Matriz de Pruebas'!F3:F989,"Falló")+COUNTIF('Matriz de Pruebas'!F3:F989,"Bloqueado"))/COUNTA('Matriz de Pruebas'!F3:F989),0) -> 0.0028248588
K8: DESGLOSE POR PRIORIDAD
A9: BARRA DE AVANCE GENERAL | K9: Prioridad | L9: Total | M9: Fallaron | N9: % Fallo
A10: =IFERROR(REPT("█",ROUND(COUNTIF('Matriz de Pruebas'!F3:F19,"Pasó")/COUNTA('Matriz de Pruebas'!F3:F19)*50,0))&REPT("░",50-ROUND(COUNTIF('Matriz de Pruebas'!F3:F19,"Pasó")/COUNTA('Matriz de Pruebas'!F3:F19)*50,0)),"Sin datos") -> ░░░░░░░░░░░░░░░░░░░░░░░░░░░░░░░░░░░░░░░░░░░░░░░░░░ | K10: Critico | L10: =COUNTIF('Matriz de Pruebas'!E3:E989,"Critico") -> 31 | M10: {=SUMPRODUCT((EXACT('Matriz de Pruebas'!E3:E989,"Critico"))*(EXACT('Matriz de Pruebas'!F3:F989,"Falló")))} -> 2 | N10: {=IFERROR(SUMPRODUCT((EXACT('Matriz de Pruebas'!E3:E989,"Critico"))*(EXACT('Matriz de Pruebas'!F3:F989,"Falló")))/COUNTIF('Matriz de Pruebas'!E3:E989,"Critico"),0)} -> 0.064516129
K11: Alta | L11: =COUNTIF('Matriz de Pruebas'!E3:E989,"Alta") -> 275 | M11: {=SUMPRODUCT((EXACT('Matriz de Pruebas'!E3:E989,"Alta"))*(EXACT('Matriz de Pruebas'!F3:F989,"Falló")))} -> 0 | N11: {=IFERROR(SUMPRODUCT((EXACT('Matriz de Pruebas'!E3:E989,"Alta"))*(EXACT('Matriz de Pruebas'!F3:F989,"Falló")))/COUNTIF('Matriz de Pruebas'!E3:E989,"Alta"),0)} -> 0
A12: DESGLOSE POR ESTADO | K12: Media | L12: =COUNTIF('Matriz de Pruebas'!E3:E989,"Media") -> 390 | M12: {=SUMPRODUCT((EXACT('Matriz de Pruebas'!E3:E989,"Media"))*(EXACT('Matriz de Pruebas'!F3:F989,"Falló")))} -> 0 | N12: {=IFERROR(SUMPRODUCT((EXACT('Matriz de Pruebas'!E3:E989,"Media"))*(EXACT('Matriz de Pruebas'!F3:F989,"Falló")))/COUNTIF('Matriz de Pruebas'!E3:E989,"Media"),0)} -> 0
A13: Estado | B13: Cantidad | C13: % del Total | D13: Tendencia | K13: Baja | L13: =COUNTIF('Matriz de Pruebas'!E3:E989,"Baja") -> 4 | M13: {=SUMPRODUCT((EXACT('Matriz de Pruebas'!E3:E989,"Baja"))*(EXACT('Matriz de Pruebas'!F3:F989,"Falló")))} -> 0 | N13: {=IFERROR(SUMPRODUCT((EXACT('Matriz de Pruebas'!E3:E989,"Baja"))*(EXACT('Matriz de Pruebas'!F3:F989,"Falló")))/COUNTIF('Matriz de Pruebas'!E3:E989,"Baja"),0)} -> 0
A14: ✅ Pasó | B14: =COUNTIF('Matriz de Pruebas'!F3:F989,"Pasó") -> 266 | C14: =IFERROR(COUNTIF('Matriz de Pruebas'!F3:F19,"Pasó")/COUNTA('Matriz de Pruebas'!F3:F19),0) -> 0 | D14: =REPT("▓",ROUND(IFERROR(COUNTIF('Matriz de Pruebas'!F3:F19,"Pasó")/COUNTA('Matriz de Pruebas'!F3:F19),0)*20,0))
A15: ❌ Falló | B15: =COUNTIF('Matriz de Pruebas'!F3:F989,"Falló") -> 2 | C15: =IFERROR(COUNTIF('Matriz de Pruebas'!F3:F19,"Falló")/COUNTA('Matriz de Pruebas'!F3:F19),0) -> 0 | D15: =REPT("▓",ROUND(IFERROR(COUNTIF('Matriz de Pruebas'!F3:F19,"Falló")/COUNTA('Matriz de Pruebas'!F3:F19),0)*20,0))
A16: 🔄 En Progreso | B16: =COUNTIF('Matriz de Pruebas'!F3:F989,"En Progreso") -> 1 | C16: =IFERROR(COUNTIF('Matriz de Pruebas'!F3:F19,"En Progreso")/COUNTA('Matriz de Pruebas'!F3:F19),0) -> 0 | D16: =REPT("▓",ROUND(IFERROR(COUNTIF('Matriz de Pruebas'!F3:F19,"En Progreso")/COUNTA('Matriz de Pruebas'!F3:F19),0)*20,0))
A17: ⏳ Pendiente | B17: =COUNTIF('Matriz de Pruebas'!F3:F989,"Pendiente") -> 439 | C17: =IFERROR(COUNTIF('Matriz de Pruebas'!F3:F19,"Pendiente")/COUNTA('Matriz de Pruebas'!F3:F19),0) -> 1 | D17: =REPT("▓",ROUND(IFERROR(COUNTIF('Matriz de Pruebas'!F3:F19,"Pendiente")/COUNTA('Matriz de Pruebas'!F3:F19),0)*20,0)) -> ▓▓▓▓▓▓▓▓▓▓▓▓▓▓▓▓▓▓▓▓
A18: 🚫 Bloqueado | B18: =COUNTIF('Matriz de Pruebas'!F3:F989,"Bloqueado") -> 0 | C18: =IFERROR(COUNTIF('Matriz de Pruebas'!F3:F19,"Bloqueado")/COUNTA('Matriz de Pruebas'!F3:F19),0) -> 0 | D18: =REPT("▓",ROUND(IFERROR(COUNTIF('Matriz de Pruebas'!F3:F19,"Bloqueado")/COUNTA('Matriz de Pruebas'!F3:F19),0)*20,0))

Sheet Matriz de Pruebas
A1: 🧪 MATRIZ DE SEGUIMIENTO DE PRUEBAS
A2: ID | B2: Escenario de Prueba | C2: Módulo | D2: Submódulo | E2: Prioridad | F2: Estado | G2: Resultado Esperado | H2: Resultado Obtenido | I2: Vinculación Bug (ID Jira) | J2: Responsable QA | K2: Responsable Negocio (UAT) | L2: Responsable Dev | M2: Notas / Evidencia | N2: Fecha Ejecución | O2: Rol Usuario | P2: Pasos | Q2: Impacto | R2: Probabilidad | S2: Escenario Dependiente | T2: Tipo Escenario | U2: Tipo
A3: REC 001 | B3: Validar botón primario único azul al consultar recepciones Disponibles con filtro fecha válido | C3: Finanzas | D3: Recepciones | E3: Media | F3: Pendiente | G3: Solo un botón primario visible en pantalla el "Exportar CSV" | J3: Marco Vezquez | K3: Nelva Flores | L3: David Montes | M3: Evidencia visual UI | O3: Proveedor – Mercancía | P3: 1.Login 2.Seleccionar fechas válidas 3.Consultar 4.Validar botones | Q3: Bajo | R3: Alta | T3: Consulta | U3: FrontEnd
A4: REC 002 | B4: Por default no presentar información hasta que el usuario seleccione los criterios de busqueda | C4: Finanzas | D4: Recepciones | E4: Media | F4: Pendiente | G4: Sin consulta de información | J4: Marco Vezquez | K4: Nelva Flores | L4: David Montes | M4: Evidencia visual UI | O4: Cualquie Rol | P4: Seleccionar opción de recepción | Q4: Bajo | R4: Alta | T4: Consulta | U4: FrontEnd
A5: REC 003 | B5: Validar el botón de limpiar, el cual limpia filtros de busqueda, consulta e información que exista cargada en pantalla | C5: Finanzas | D5: Recepciones | E5: Media | F5: Pendiente | G5: Limpia la pantalla de toda la información cargada | J5: Marco Vezquez | K5: Nelva Flores | L5: David Montes | M5: Evidencia visual UI | O5: Proveedor – Mercancía | P5: 1.Login 2.Seleccionar fechas válidas 3.Consultar 4.Validar botones | Q5: Bajo | R5: Alta | T5: Consulta | U5: FrontEnd
A6: REC 004 | B6: El campo de id de proveedor llenarno por default cuando tenga el rol de proveedor | C6: Finanzas | D6: Recepciones | E6: Media | F6: Pendiente | G6: Id del proveedor precargado | J6: Marco Vezquez | K6: Nelva Flores | L6: David Montes | M6: Evidencia visual UI | O6: Proveedor – Mercancía | Q6: Bajo | R6: Alta | T6: Consulta | U6: FrontEnd
A7: REC 005 | B7: El campo de id de proveedor permitir seleccionar cuando tenga el rol diferente a proveedor | C7: Finanzas | D7: Recepciones | E7: Media | F7: Pendiente | G7: Campo de captura activo | J7: Marco Vezquez | K7: Nelva Flores | L7: David Montes | M7: Evidencia visual UI | O7: Rol diferente a proveedor | Q7: Bajo | R7: Alta | T7: Consulta | U7: FrontEnd
A8: REC 006 | B8: Modal obligatorio cancelar recepción Disponible sin factura | C8: Finanzas | D8: Recepciones | E8: Media | F8: Pendiente | G8: Modal confirmación obligatorio antes de cancelar | J8: Marco Vezquez | K8: Nelva Flores | L8: David Montes | M8: Captura modal | O8: Proveedor – Mercancía | P8: 1.Filtrar 2.Seleccionar recepción 3.Cancelar | Q8: Alto | R8: Media | T8: Actualización | U8: FrontEnd
A9: REC 007 | B9: Calendario de filtro de fechas fijo sin desplazamiento | C9: Finanzas | D9: Recepciones | E9: Media | F9: Pendiente | G9: Calendario no genera scroll UI | J9: Marco Vezquez | K9: Nelva Flores | L9: David Montes | O9: Proveedor – Transporte | P9: 1.Abrir calendario | Q9: Medio | R9: Media | T9: Consulta | U9: FrontEnd
A10: REC 008 | B10: Validar formato moneda y fecha | C10: Finanzas | D10: Recepciones | E10: Media | F10: Pendiente | G10: $000.00 y dd/mm/yyyy correctos | J10: Marco Vezquez | K10: Nelva Flores | L10: David Montes | O10: Proveedor – Servicios | P10: 1.Consultar registros | Q10: Bajo | R10: Media | T10: Consulta | U10: FrontEnd
A11: REC 009 | B11: Validar los colores de cada estatus de la recepción que retorna el API Catálogo de catálogos | C11: Finanzas | D11: Recepciones | E11: Media | F11: Pendiente | G11: Colores consistentes por estatus | J11: Marco Vezquez | K11: Nelva Flores | L11: David Montes | O11: Proveedor – Indirectos | P11: 1.Consultar grid | Q11: Medio | R11: Media | T11: Consulta | U11: FrontEnd
A12: REC 010 | B12: Validar paginación centrada con 10 registros exactos | C12: Finanzas | D12: Recepciones | E12: Media | F12: Pendiente | G12: Paginación centrada y fija en 10 | J12: Marco Vezquez | K12: Nelva Flores | L12: David Montes | O12: Analista Financiero – General | P12: 1.Consultar lista | Q12: Medio | R12: Baja | T12: Consulta | U12: FrontEnd
A13: REC 011 | B13: Persistencia filtros navegación de pantalla secundaria primaria | C13: Finanzas | D13: Recepciones | E13: Media | F13: Pendiente | G13: Filtros se mantienen | J13: Marco Vezquez | K13: Nelva Flores | L13: David Montes | O13: Analista Financiero – Especializado | P13: 1.Filtrar 2.Navegar 3.Regresar | Q13: Alto | R13: Media | T13: Consulta | U13: FrontEnd
A14: REC 012 | B14: Validar columnas completas Admin Funcional | C14: Finanzas | D14: Recepciones | E14: Media | F14: Pendiente | G14: Todas columnas visibles | J14: Marco Vezquez | K14: Nelva Flores | L14: David Montes | O14: Administrador Funcional | P14: 1.Consultar grid | Q14: Alto | R14: Media | T14: Consulta | U14: FrontEnd
A15: REC 013 | B15: Mensaje UX sin resultados | C15: Finanzas | D15: Recepciones | E15: Media | F15: Pendiente | G15: Mensaje claro sin error técnico | J15: Marco Vezquez | K15: Nelva Flores | L15: David Montes | O15: Comprador | P15: 1.Buscar UUID inválido | Q15: Medio | R15: Alta | T15: Error | U15: FrontEnd
A16: REC 014 | B16: Calendario sin movimiento rol Gerente Transporte | C16: Finanzas | D16: Recepciones | E16: Media | F16: Pendiente | G16: UI estable | J16: Marco Vezquez | K16: Nelva Flores | L16: David Montes | O16: Gerente de Transporte | P16: 1.Abrir fechas | Q16: Medio | R16: Media | T16: Consulta | U16: FrontEnd
A17: REC 015 | B17: Consulta válida filtros fecha+estatus Disponible con factura | C17: Finanzas | D17: Recepciones | E17: Media | F17: Pendiente | G17: Datos correctos retornados | J17: Marco Vezquez | K17: Nelva Flores | L17: David Montes | O17: Proveedor – Mercancía | P17: 1.Aplicar filtros | Q17: Alto | R17: Alta | T17: Consulta | U17: FrontEnd
A18: REC 016 | B18: Consulta UUID exacto Consumida manual sin factura | C18: Finanzas | D18: Recepciones | E18: Media | F18: Pendiente | G18: Registro único correcto | J18: Marco Vezquez | K18: Nelva Flores | L18: David Montes | O18: Proveedor – Transporte | P18: 1.Ingresar UUID | Q18: Alto | R18: Media | T18: Consulta | U18: FrontEnd
A19: REC 017 | B19: Consulta documento parcial con múltiples coincidencias | C19: Finanzas | D19: Recepciones | E19: Media | F19: Pendiente | G19: Registros filtrados correctamente | J19: Marco Vezquez | K19: Nelva Flores | L19: David Montes | O19: Proveedor – Servicios | P19: 1.Ingresar doc parcial | Q19: Medio | R19: Media | T19: Consulta | U19: FrontEnd
A20: REC 018 | B20: Consulta acceso restringido tipo proveedor distinto | C20: Finanzas | D20: Recepciones | E20: Media | F20: Pendiente | G20: Acceso denegado | J20: Marco Vezquez | K20: Nelva Flores | L20: David Montes | O20: Proveedor – Indirectos | P20: 1.Intentar visualizar otro tipo | Q20: Alto | R20: Media | T20: Restricción | U20: FrontEnd
... A26: REC 024 | B26: Exportación XLSX alto volumen integridad datos | C26: Finanzas | D26: Recepciones | E26: Media | F26: Pendiente | G26: Archivo completo sin pérdida | J26: Marco Vezquez | K26: Nelva Flores | L26: David Montes | O26: Administrador del Sistema | P26: 1.Exportar XLSX | Q26: Alto | R26: Media | T26: Consulta | U26: FrontEnd
A27: REC 025 | B27: Llevar a una pantalla secundaria para relacionar factura CFDI válido Disponible | C27: Finanzas | D27: Recepciones | E27: Media | F27: Pendiente | G27: Relación exitosa | J27: Marco Vezquez | K27: Nelva Flores | L27: David Montes | O27: Proveedor – Mercancía | P27: 1.Seleccionar recepción 2.Relacionar | Q27: Alto | R27: Alta | S27: REC011 | T27: Actualización | U27: FrontEnd
A28: REC 026 | B28: Llevar a una pantalla secundaria para relación manual UUID válido coincidente | C28: Finanzas | D28: Recepciones | E28: Media | F28: Pendiente | G28: Relación completada | J28: Marco Vezquez | K28: Nelva Flores | L28: David Montes | O28: Proveedor – Transporte | P28: 1.Ingresar UUID válido | Q28: Alto | R28: Media | S28: REC012 | T28: Actualización | U28: FrontEnd
A29: REC 027 | B29: Llevar a una pantalla secundaria para ver artículos en Consumida con detalle completo | C29: Finanzas | D29: Recepciones | E29: Media | F29: Pendiente | G29: Información correcta | J29: Marco Vezquez | K29: Nelva Flores | L29: David Montes | O29: Proveedor – Servicios | P29: 1.Ver artículos | Q29: Medio | R29: Media | T29: Consulta | U29: FrontEnd
A30: REC 028 | B30: Llevar a una pantalla secundaria para cancelar recepción Disponible sin factura | C30: Finanzas | D30: Recepciones | E30: Media | F30: Pendiente | G30: Estatus cambia a 7 | J30: Marco Vezquez | K30: Nelva Flores | L30: David Montes | O30: Proveedor – Indirectos | P30: 1.Cancelar | Q30: Alto | R30: Media | S30: REC011 | T30: Actualización | U30: FrontEnd
A31: REC 029 | B31: Transición válida Disponible→Consumida | C31: Finanzas | D31: Recepciones | E31: Media | F31: Pendiente | G31: Cambio correcto estatus | J31: Marco Vezquez | K31: Nelva Flores | L31: David Montes | O31: Analista Financiero – General | P31: 1.Ejecutar acción | Q31: Alto | R31: Alta | S31: REC011 | T31: Actualización | U31: FrontEnd
A32: REC 030 | B32: Transición Consumida→Contable | C32: Finanzas | D32: Recepciones | E32: Media | F32: Pendiente | G32: Estatus 3 aplicado | J32: Marco Vezquez | K32: Nelva Flores | L32: David Montes | O32: Analista Financiero – Especializado | P32: 1.Procesar contable | Q32: Alto | R32: Media | S32: REC025 | T32: Actualización | U32: FrontEnd
A33: REC 031 | B33: Flujo Contable→Pago | C33: Finanzas | D33: Recepciones | E33: Media | F33: Pendiente | G33: Estatus 5 | J33: Marco Vezquez | K33: Nelva Flores | L33: David Montes | O33: Gerente Financiero | P33: 1.Procesar pago | Q33: Alto | R33: Alta | S33: REC026 | T33: Actualización | U33: FrontEnd
A34: REC 032 | B34: Flujo Pago→Pagada cierre | C34: Finanzas | D34: Recepciones | E34: Media | F34: Pendiente | G34: Estatus 6 | J34: Marco Vezquez | K34: Nelva Flores | L34: David Montes | O34: Administrador del Sistema | P34: 1.Validar pago | Q34: Alto | R34: Alta | S34: REC027 | T34: Actualización | U34: FrontEnd
A35: REC 033 | B35: Rechazo contable desde Consumida | C35: Finanzas | D35: Recepciones | E35: Media | F35: Pendiente | G35: Estatus 4 | J35: Marco Vezquez | K35: Nelva Flores | L35: David Montes | O35: Analista Financiero – Especializado | P35: 1.Rechazar | Q35: Alto | R35: Media | T35: Actualización | U35: FrontEnd
A36: REC 034 | B36: Cancelar recepción Pagada no permitido | C36: Finanzas | D36: Recepciones | E36: Media | F36: Pendiente | G36: Acción bloqueada | J36: Marco Vezquez | K36: Nelva Flores | L36: David Montes | O36: Analista Financiero – General | P36: 1.Intentar cancelar | Q36: Alto | R36: Alta | T36: Restricción | U36: FrontEnd
A37: REC 035 | B37: Relacionar factura en Cancelada no permitido | C37: Finanzas | D37: Recepciones | E37: Media | F37: Pendiente | G37: Bloqueo acción | J37: Marco Vezquez | K37: Nelva Flores | L37: David Montes | O37: Proveedor – Transporte | P37: 1.Intentar relacionar | Q37: Alto | R37: Media | T37: Restricción | U37: FrontEnd
A38: REC 036 | B38: Validar invisibilidad de estatus de recepción Borrado lógico | C38: Finanzas | D38: Recepciones | E38: Media | F38: Pendiente | G38: Registro no visible | J38: Marco Vezquez | K38: Nelva Flores | L38: David Montes | O38: Administrador Funcional | P38: 1.Buscar registro | Q38: Alto | R38: Media | T38: Restricción | U38: FrontEnd
A39: REC 037 | B39: Transición inválida Disponible→Pagada | C39: Finanzas | D39: Recepciones | E39: Media | F39: Pendiente | G39: API rechaza operación | J39: Marco Vezquez | K39: Nelva Flores | L39: David Montes | O39: Gerente Financiero | P39: 1.Intentar salto | Q39: Alto | R39: Media | T39: Restricción | U39: FrontEnd
A40: REC 038 | B40: Acceso datos proveedor distinto bloqueado | C40: Finanzas | D40: Recepciones | E40: Media | F40: Pendiente | G40: Acceso denegado | J40: Marco Vezquez | K40: Nelva Flores | L40: David Montes | O40: Proveedor – Mercancía | P40: 1.Intentar acceso | Q40: Alto | R40: Alta | T40: Seguridad | U40: FrontEnd
A41: REC 039 | B41: Columnas sensibles de columnas ocultas para rol de proveedor (Columna Id Proveedor, Nombre Proveedor) | C41: Finanzas | D41: Recepciones | E41: Media | F41: Pendiente | G41: Columnas restringidas | J41: Marco Vezquez | K41: Nelva Flores | L41: David Montes | O41: Gerente Comercial | P41: 1.Validar columnas | Q41: Medio | R41: Media | T41: Restricción | U41: FrontEnd
A42: REC 040 | B42: Acceso URL sin autenticación | C42: Finanzas | D42: Recepciones | E42: Media | F42: Pendiente | G42: Redirección login | J42: Marco Vezquez | K42: Nelva Flores | L42: David Montes | O42: Usuario anónimo | P42: 1.Abrir URL | Q42: Alto | R42: Alta | T42: Seguridad | U42: FrontEnd
A43: REC 041 | B43: Manipulación payload UUID backend | C43: Finanzas | D43: Recepciones | E43: Media | F43: Pendiente | G43: Rechazo seguridad | J43: Marco Vezquez | K43: Nelva Flores | L43: David Montes | O43: Administrador del Sistema | P43: 1.Alterar request | Q43: Alto | R43: Alta | T43: Seguridad | U43: FrontEnd
A44: REC 042 | B44: UUID inválido longitud incorrecta | C44: Finanzas | D44: Recepciones | E44: Media | F44: Pendiente | G44: Validación error | J44: Marco Vezquez | K44: Nelva Flores | L44: David Montes | O44: Proveedor – Servicios | P44: 1.Ingresar inválido | Q44: Medio | R44: Alta | T44: Error | U44: FrontEnd
A45: REC 043 | B45: Fecha mayor 6 meses bloqueada | C45: Finanzas | D45: Recepciones | E45: Media | F45: Pendiente | G45: Error validación | J45: Marco Vezquez | K45: Nelva Flores | L45: David Montes | O45: Gerente Comercial | P45: 1.Filtrar fechas inválidas | Q45: Alto | R45: Alta | T45: Error | U45: FrontEnd
...

Sheet Listado Issue Abiertos
A1: Incidente | B1: Nivel | C1: Responsable | D1: Módulo | E1: Pantalla | F1: Revisión DEV | G1: Ajuste DEV | H1: Validado QA | I1: Comentario QA | J1: Fecha Reporte | K1: Fecha Resuelto
A2: Ajustar el documento PDF que se genera automáticamente cuando un proveedor no carga su nota de crédito. El campo «Folio Fiscal Relacionado» no está tomando el valor del elemento CfdiRelacionado (UUID). | B2: Medio | C2: Roberto | D2: Fiscal | E2: Notas de crédito | F2: x | G2: D | H2: x | J2: 46268
A3: Ajustar el proceso de sincronización de facturas y notas de crédito. En cada consulta, registrar la respuesta de SAP con los siguientes datos: documento SAP, mensaje y fecha contable del documento procesado. Si el registro no cambia de estatus, no volver a procesarlo, a fin de evitar información duplicada. | B3: Alto | C3: Roberto | D3: Fiscal | E3: Facturación | F3: x | G3: D | H3: 1 | J3: 46283
A4: Al cancelar una nota de crédito (NC), el cambio de estatus se realiza correctamente; sin embargo, falta implementar el siguiente flujo: cambiar a «Recibido parcial» el estatus de la factura relacionada y el de todas sus notas de crédito asociadas. | B4: Alto | C4: David | D4: Fiscal | E4: Notas de crédito | F4: x | H4: 1 | I4: Al intentar cancelar la NC marca error 403 21/09/2026 Aun no esta corregido. | J4: 46269
A5: Al cancelar una factura con estatus «Recibido parcial», cambiar automáticamente a «Cancelado» el estatus de todas las notas de crédito relacionadas y a «Disponible» el estatus de la recepción. Actualmente, este flujo está implementado. | B5: Alto | C5: David | D5: Fiscal | E5: Facturación | F5: x | H5: 1 | I5: Al intentar cancelar la NC marca error 403 | J5: 46284
A6: El estado de cuenta está incluyendo recepciones, facturas y notas de crédito canceladas. Estos documentos no deben mostrarse en el estado de cuenta. | B6: Alto | C6: Fernando | D6: Finanzas | E6: Estado de Cuenta | F6: x | G6: D | H6: x | I6: 21/09/2026 Ya se encuentra corregido, | J6: 46242
A7: Al cancelar una nota de crédito (NC), esta continúa considerándose en la sumatoria de la relación de la factura. Las notas de crédito canceladas no deben incluirse en dicha suma. | B7: Alto | C7: Fernando | D7: Fiscal | E7: Facturación | F7: x | G7: D | H7: x | J7: 46282
A8: Al intentar cargar un complemento de pago, el sistema muestra un error 403. | B8: Alto | C8: Fernando | D8: Fiscal | E8: Complemento Pago | F8: x | H8: 1 | J8: 46282
A9: Cuando un usuario inicia sesión por primera vez, revisar el macrorrol asignado para configurar de forma predeterminada el perfil genérico correspondiente y evitar que se muestre una pantalla en blanco. | B9: Alto | C9: Fernando | D9: Seguridad | E9: Seguridad | F9: x | G9: D | H9: 1 | J9: 46283
A10: En la pantalla de detalle de Carta Porte, el ID del usuario que realizó el registro se muestra como un valor numérico. Se debe mostrar el nombre del usuario. (Ocultar etiqueta) | B10: Bajo | C10: Fernando | D10: Finanzas | E10: Carta Porte | F10: x | G10: D | H10: x | J10: 46283
A11: En la pantalla de detalle, la información de las columnas «Número de documento» y «Documento SAP» está invertida. Además, quitar la columna «Fecha de actualización» para evitar que se muestre la barra de desplazamiento. | B11: Medio | C11: Fernando | D11: Finanzas | E11: Pagos | F11: x | G11: D | H11: x | J11: 46283
A12: En el reporte de detalle del pago, ajustar el nombre del archivo CSV al formato: detalle_pago_NumeroDocSAP_yyyymmdd.hh24mmss.csv. | B12: Bajo | C12: Fernando | D12: Finanzas | E12: Pagos | F12: x | G12: D | H12: x | I12: 25/09/2026 Corregido: pagos_20260925.105425 | J12: 46286
A13: Agregar la columna «Tipo de recepción» al proceso de descarga de recepciones de proveedores de mercancía. Consultar la historia de usuario: https://falabella.atlassian.net/browse/STM-1528. | B13: Alto | C13: Josue Lopez | D13: Finanzas | E13: Listado Recepciones | F13: x | H13: x | I13: Pendiente de validar | J13: 46273
A14: Ajustar el proceso de registro de recepciones de Carta Porte para publicar el tipo de recepción de los viajes. | B14: Alto | C14: Josue Lopez | D14: Finanzas | E14: Carta Porte | F14: x | H14: x | I14: Pendiente de validar | J14: 46283
A15: Crear el proceso para registrar los gastos adicionales generados en los viajes de los transportistas. | B15: Alto | C15: Josue Lopez | D15: Finanzas | E15: Carta Porte | F15: x | H15: Y | J15: 46283
A16: Agregar la columna «Tipo de recepción» a la notificación de recepciones pendientes de relacionar con una factura. (Colocar la descripción del tipo de recepción), validar que la recepción sean solo las disponibles (Revisar el back de recepciones) | B16: Alto | C16: Josue Lopez | D16: Finanzas | E16: Listado Recepciones | F16: x | H16: x | J16: 46283
A17: Con el usuario zedlav.sd87@gmail.com, al cambiar de institución o país, se siguen mostrando las tarjetas de México. | B17: Alto | C17: Oscar Bonelli | D17: Seguridad | E17: Seguridad | F17: x | G17: x | H17: x | I17: 21/09/2026 Se encuentra corregido. | J17: 46275
A18: Quitar la columna «Estatus de OC» de la pantalla y del reporte de Three Way Match. Además, el estatus de la recepción no coincide con el catálogo CatEstatusRecepcion. | B18: Alto | C18: Oscar Bonelli | D18: Finanzas | E18: Three way match | F18: x | G18: x | H18: x | J18: 46276
A19: En la pantalla de detalle de acuerdos comerciales no se muestra el nombre del proveedor; en su lugar, aparece el valor «ND». | B19: Bajo | C19: Oscar Bonelli | D19: Finanzas | E19: Descuentos Comercial | F19: x | G19: x | H19: x | I19: 21/09/2026 Se encuentra corregido. | J19: 46282
A20: Ajustar el nombre del archivo descargado del reporte de Three Way Match al siguiente formato: three_way_match_yyyymmdd.hh24mmss.csv o three_way_match_yyyymmdd.hh24mmss.xlsx, según corresponda. | B20: Bajo | C20: Oscar Bonelli | D20: Finanzas | E20: Three way match | F20: x | G20: x | H20: x | I20: 25/09/2026 Corregido Excel: three_way_match_20260925_122425 CSV: three_way_match_20260925_122523 | J20: 46283
A21: Quitar el grid de la nota de crédito y de la relación de factura, ya que la información se repite en el grid inferior. | B21: Bajo | C21: Oscar Bonelli | D21: Finanzas | E21: Descuentos Comercial | F21: x | G21: x | H21: x | I21: 21/09/2026 Aun no se encuentra corregido. 22/09/2026 Corregido. | J21: 46283
A22: Ajustar la pantalla de detalle del descuento comercial. Debajo de la relación de la nota de crédito, agregar un grid con las órdenes de compra que conforman el descuento comercial y las siguientes columnas: Orden de compra, Monto recibido, Fecha de recepción, Tipo de descuento y Monto de descuento. | B22: Alto | C22: Oscar Bonelli | D22: Finanzas | E22: Descuentos Comercial | F22: x | H22: 1
A23: Eliminar todos los catálogos cuyo nombre contenga «test» / «Prueba» y conservar únicamente los que se utilizarán en producción. Antes de eliminarlos, respaldar la información por si se identifican errores o relaciones con otros catálogos. | B23: Alto | C23: Ricardo | D23: Catálogo de Catálogos | E23: Catálogo de Catálogos | F23: x | G23: D | H23: x | I23: 21/09/2026 Validado, se encuentra corregido (QA). | J23: 46283
A24: Agregar la columna «Tipo de recepción». Consultar la historia de usuario: https://falabella.atlassian.net/browse/STM-1526. | B24: Alto | C24: Ricardo | D24: Finanzas | E24: Recepciones MIGO | F24: x | G24: D | H24: 1 | J24: 46279
A25: [Funcional][Control de acceso - Rol/Atributo] Implementar la gestión y asignación de atributos por rol, en sustitución de la administración por usuario. | B25: Alto | C25: Ricardo | D25: Seguridad | E25: Seguridad | F25: x | G25: x | H25: x | I25: Se validan correctamente los Criterios de Aceptación en ambiente QA el 24/09/2026. El comportamiento cumple con el resultado esperado. Se procede a cerrar el ticket. | J25: 46274 | K25: 46289
A26: [Funcional][Seguridad / Rol Atributo] No permite seleccionar valores de los atributos de segmentación | B26: Alto | C26: Ricardo | D26: Seguridad | E26: Seguridad | F26: x | G26: 1 | H26: 1 | I26: Ya se muestra la lista desplegable de cada atributo. Falta validar que también se despliegue para «Empresa», «Grupo proveedor» y «Tipo rebate», además de ajustar aspectos de UX/UI. También se validó el filtrado de datos con el atributo «Tipo proveedor = Transporte», pero aún no funciona. | J26: 46269
A27: [Backend][Global: Control de Acceso] Eventos relacionados con permisos incorrectos permiten ejecutar acciones no autorizadas | B27: Alto | C27: Ricardo | D27: Seguridad | E27: Seguridad | F27: x | G27: 1 | H27: 1 | I27: El catálogo «Permiso» ha sido modificado y homologado, adicionalmente que la matriz de de "Catálogos x Permisos" ha sido subida al ticket de Jira para que se aplique la actualización correspondiente. | J27: 46269
A28: [Funcional][Catálogos: Elementos] Filtro "Catálogo Padre" muestra catálogos sin relación con el catálogo consultado | B28: Medio | C28: Ricardo | D28: Catálogo de Catálogos | E28: Catálogo de Catálogos | F28: x | G28: x | H28: x | I28: Se validan correctamente los Criterios de Aceptación en ambiente QA el 21/09/2026. El comportamiento cumple con el resultado esperado. Se procede a cerrar el ticket. | J28: 46286
A29: [Funcional][Catálogos: Conversiones] La consulta no muestra en el grid las fechas de inicio y fin de los elementos de conversión | B29: Bajo | C29: Ricardo | D29: Catálogo de Catálogos | E29: Catálogo de Catálogos | F29: x | G29: x | H29: x | I29: Se validan correctamente los Criterios de Aceptación en ambiente QA el 21/09/2026. El comportamiento cumple con el resultado esperado. Se procede a cerrar el ticket. | J29: 46286
A30: Revisar los xml de recepciones debido a error de parcero en el proceso de registro de recepciones en FBC | B30: Alto | C30: Josue Lopez | D30: Finanzas | E30: Listado Recepciones | F30: x | H30: x | J30: 46283
A31: No se visualizan las facturas pendientes de pago en el estado de cuenta, proveedor trabicel | B31: Alto | C31: Fernando | D31: Finanzas | E31: Estado de Cuenta | F31: x | G31: D | H31: 1 | I31: 21/09/2026 Se encuentra coregido. | J31: 46286
A32: Recepciones migo no sigue formato de descarga CSV, se guarda de esta manera: recepciones-migo-MIGO-20260918-003612306_20260921_15.53.20 | B32: Bajo | C32: Ricardo | D32: Finanzas | E32: Recepciones MIGO | F32: x | G32: D | H32: x | I32: 23/09/2026 Se encuentra corregido. | J32: 46286
A33: CSV de cátalo de usuarios descarga con este nombre: catalogo-usuarios-21-09-2026-16-26 debería considerar formato nombre_yyyymmdd.hh24mmss | B33: Bajo | C33: Ricardo | D33: Seguridad | E33: Catálogo de Catálogos | F33: x | G33: D | H33: 1 | J33: 46286
A34: CSV de Aplicativo Evento descarga con este nombre: aplicativo-evento-21-09-2026-16-31 debería considerar formato nombre_yyyymmdd.hh24mmss | B34: Bajo | C34: Ricardo | D34: Seguridad | E34: Seguridad | F34: x | G34: D | H34: x | I34: 23/09/2026 Se encuentra corregido. | J34: 46286
A35: CSV de Perfil Aplicativo descarga con este nombre: perfil-aplicativo-21-09-2026-16-32 debería considerar formato nombre_yyyymmdd.hh24mmss | B35: Bajo | C35: Ricardo | D35: Seguridad | E35: Seguridad | F35: x | G35: D | H35: x | I35: 23/09/2026 Se encuentra corregido. | J35: 46286
A36: En cualquier opción de Control de Acceso permite seleccionar fechas con días posteriores | B36: Bajo | C36: Ricardo | D36: Seguridad | E36: Seguridad | F36: x | G36: D | H36: x | J36: 46286
A37: Inicio/Herramientas y Utilerías/Configuración de Parámetros: el nombre en la descarga en formato Excel y CSV, no se guarda de acuerdo con el formato: nombre_yyyymmdd.hh24mmss Excel: parametros_20260922_0810.xlsx CSV: parametros_20260922_0811.csv | B37: Bajo | C37: Ricardo | D37: Catálogo de Catálogos | E37: Catálogo de Catálogos | G37: D | H37: x | J37: 46287
A38: Inicio/Herramientas y Utilerías/Gestión de Catálogos/Proveedores: el nombre en la descarga en formato Excel y CSV, no se guarda de acuerdo con el formato: nombre_yyyymmdd.hh24mmss Excel: proveedores_2026-09-22.xlsx CSV: proveedores_2026-09-22.csv | B38: Bajo | C38: Ricardo | D38: Catálogo de Catálogos | E38: Catálogo de Catálogos | G38: D | H38: 1 | J38: 46287
A39: Inicio/Herramientas y Utilerías/Gestión de Catálogos/Bloqueo de Proveedores: el nombre en la descarga en formato Excel y CSV, no se guarda de acuerdo con el formato: nombre_yyyymmdd.hh24mmss Excel: bloqueos_proveedores_2026-09-22.xlsx CSV: bloqueos_proveedores_2026-09-22.csv | B39: Bajo | C39: Ricardo | D39: Catálogo de Catálogos | E39: Catálogo de Catálogos | G39: D | H39: 1 | J39: 46287
A40: Inicio/Herramientas y Utilerías/Gestión de Catálogos/Catálogos: el nombre en la descarga en formato Excel y CSV, no se guarda de acuerdo con el formato: nombre_yyyymmdd.hh24mmss Excel: catalogos_20260922143201.xlsx CSV: catalogos_20260922143136.csv | B40: Bajo | C40: Ricardo | D40: Catálogo de Catálogos | E40: Catálogo de Catálogos | G40: D | H40: 1 | J40: 46287
...

Sheet Carga por Responsable
A1: CARGA DE INCIDENCIAS POR RESPONSABLE
A2: 48 incidencias abiertas · desglose por nivel de complejidad
A3: Responsable | B3: Total asignado | C3: Alto | D3: Medio | E3: Bajo | F3: Cerrados | G3: Pendientes
A4: Ricardo | B4: =COUNTIF('Listado Issue Abiertos'!$C$2:$C$217,$A4) -> 19 | C4: =COUNTIFS('Listado Issue Abiertos'!$C$2:$C$217,$A4,'Listado Issue Abiertos'!$B$2:$B$217,C$3) -> 6 | D4: =COUNTIFS('Listado Issue Abiertos'!$C$2:$C$217,$A4,'Listado Issue Abiertos'!$B$2:$B$217,D$3) -> 1 | E4: =COUNTIFS('Listado Issue Abiertos'!$C$2:$C$217,$A4,'Listado Issue Abiertos'!$B$2:$B$217,E$3) -> 12 | F4: 9 | G4: =tblCargaResponsable[[#This Row],[Total asignado]]-tblCargaResponsable[[#This Row],[Cerrados]] -> 10
A5: Fernando | B5: =COUNTIF('Listado Issue Abiertos'!$C$2:$C$217,$A5) -> 14 | C5: =COUNTIFS('Listado Issue Abiertos'!$C$2:$C$217,$A5,'Listado Issue Abiertos'!$B$2:$B$217,C$3) -> 5 | D5: =COUNTIFS('Listado Issue Abiertos'!$C$2:$C$217,$A5,'Listado Issue Abiertos'!$B$2:$B$217,D$3) -> 1 | E5: =COUNTIFS('Listado Issue Abiertos'!$C$2:$C$217,$A5,'Listado Issue Abiertos'!$B$2:$B$217,E$3) -> 8 | F5: 11 | G5: =tblCargaResponsable[[#This Row],[Total asignado]]-tblCargaResponsable[[#This Row],[Cerrados]] -> 3
A6: Oscar Bonelli | B6: =COUNTIF('Listado Issue Abiertos'!$C$2:$C$217,$A6) -> 6 | C6: =COUNTIFS('Listado Issue Abiertos'!$C$2:$C$217,$A6,'Listado Issue Abiertos'!$B$2:$B$217,C$3) -> 3 | D6: =COUNTIFS('Listado Issue Abiertos'!$C$2:$C$217,$A6,'Listado Issue Abiertos'!$B$2:$B$217,D$3) -> 0 | E6: =COUNTIFS('Listado Issue Abiertos'!$C$2:$C$217,$A6,'Listado Issue Abiertos'!$B$2:$B$217,E$3) -> 3 | F6: 5 | G6: =tblCargaResponsable[[#This Row],[Total asignado]]-tblCargaResponsable[[#This Row],[Cerrados]] -> 1
A7: Josue Lopez | B7: =COUNTIF('Listado Issue Abiertos'!$C$2:$C$217,$A7) -> 5 | C7: =COUNTIFS('Listado Issue Abiertos'!$C$2:$C$217,$A7,'Listado Issue Abiertos'!$B$2:$B$217,C$3) -> 5 | D7: =COUNTIFS('Listado Issue Abiertos'!$C$2:$C$217,$A7,'Listado Issue Abiertos'!$B$2:$B$217,D$3) -> 0 | E7: =COUNTIFS('Listado Issue Abiertos'!$C$2:$C$217,$A7,'Listado Issue Abiertos'!$B$2:$B$217,E$3) -> 0 | F7: 5 | G7: =tblCargaResponsable[[#This Row],[Total asignado]]-tblCargaResponsable[[#This Row],[Cerrados]] -> 0
A8: Roberto | B8: =COUNTIF('Listado Issue Abiertos'!$C$2:$C$217,$A8) -> 2 | C8: =COUNTIFS('Listado Issue Abiertos'!$C$2:$C$217,$A8,'Listado Issue Abiertos'!$B$2:$B$217,C$3) -> 1 | D8: =COUNTIFS('Listado Issue Abiertos'!$C$2:$C$217,$A8,'Listado Issue Abiertos'!$B$2:$B$217,D$3) -> 1 | E8: =COUNTIFS('Listado Issue Abiertos'!$C$2:$C$217,$A8,'Listado Issue Abiertos'!$B$2:$B$217,E$3) -> 0 | F8: 1 | G8: =tblCargaResponsable[[#This Row],[Total asignado]]-tblCargaResponsable[[#This Row],[Cerrados]] -> 1
A9: David | B9: =COUNTIF('Listado Issue Abiertos'!$C$2:$C$217,$A9) -> 2 | C9: =COUNTIFS('Listado Issue Abiertos'!$C$2:$C$217,$A9,'Listado Issue Abiertos'!$B$2:$B$217,C$3) -> 2 | D9: =COUNTIFS('Listado Issue Abiertos'!$C$2:$C$217,$A9,'Listado Issue Abiertos'!$B$2:$B$217,D$3) -> 0 | E9: =COUNTIFS('Listado Issue Abiertos'!$C$2:$C$217,$A9,'Listado Issue Abiertos'!$B$2:$B$217,E$3) -> 0 | F9: 0 | G9: =tblCargaResponsable[[#This Row],[Total asignado]]-tblCargaResponsable[[#This Row],[Cerrados]] -> 2
A11: TOTAL GENERAL | B11: =SUM(B4:B9) -> 48 | C11: =SUM(C4:C9) -> 22 | D11: =SUM(D4:D9) -> 3 | E11: =SUM(E4:E9) -> 23 | F11: =SUM(F4:F9) -> 31 | G11: =SUM(G4:G9) -> 17

Sheet Total
A3: Etiquetas de fila | B3: Suma de Validado QA
A4: Carta Porte | B4: 0
A5: Catálogo de Catálogos | B5: 6
A6: Complemento Pago | B6: 1
A7: Descuentos Comercial | B7: 1
A8: Estado de Cuenta | B8: 1
A9: Facturación | B9: 2
A10: Listado Recepciones | B10: 0
A11: Notas de crédito | B11: 1
A12: Pagos | B12: 0
A13: Recepciones MIGO | B13: 1
A14: Seguridad | B14: 4
A15: Three way match | B15: 0
A16: (en blanco)
A17: Total general | B17: 17

Sheet Presentacion
A1: Opciones | B1: Total Escenarios | C1: Total Validados | D1: Porcentaje Validado | E1: Issue Abiertos
A2: Listado Recepciones | B2: 51 | C2: 51 | D2: =(C2/B2) -> 1 | E2: =VLOOKUP(A2,Total!$A$4:$B$25,2,FALSE) -> 0
A3: Carta Porte | B3: 50 | C3: 50 | D3: =(C3/B3) -> 1 | E3: =VLOOKUP(A3,Total!$A$4:$B$25,2,FALSE) -> 0
A4: Recepciones MIGO | B4: 52 | C4: 52 | D4: =(C4/B4) -> 1 | E4: =VLOOKUP(A4,Total!$A$4:$B$25,2,FALSE) -> 1
A5: Estado de cuenta | B5: 49 | C5: 41 | D5: =(C5/B5) -> 0.83673469 | E5: =VLOOKUP(A5,Total!$A$4:$B$25,2,FALSE) -> 1
A6: Three way match | B6: 50 | C6: 50 | D6: =(C6/B6) -> 1 | E6: =VLOOKUP(A6,Total!$A$4:$B$25,2,FALSE) -> 0
A7: Pagos | B7: 49 | C7: 49 | D7: =(C7/B7) -> 1 | E7: =VLOOKUP(A7,Total!$A$4:$B$25,2,FALSE) -> 0
A8: Descuentos Comercial | B8: 49 | C8: 45 | D8: =(C8/B8) -> 0.91836735 | E8: =VLOOKUP(A8,Total!$A$4:$B$25,2,FALSE) -> 1
A9: Facturación | B9: 47 | C9: 47 | D9: =(C9/B9) -> 1 | E9: =VLOOKUP(A9,Total!$A$4:$B$25,2,FALSE) -> 2
A10: Notas de Crédito | B10: 48 | C10: 48 | D10: =(C10/B10) -> 1 | E10: =VLOOKUP(A10,Total!$A$4:$B$25,2,FALSE) -> 1
A11: Complemento Pago | B11: 48 | C11: 48 | D11: =(C11/B11) -> 1 | E11: =VLOOKUP(A11,Total!$A$4:$B$25,2,FALSE) -> 1
A12: Catálogo de catálogos | B12: 177 | C12: 177 | D12: =(C12/B12) -> 1 | E12: =VLOOKUP(A12,Total!$A$4:$B$25,2,FALSE) -> 6
A13: Configuración de parámetros | B13: 101 | C13: 101 | D13: =(C13/B13) -> 1 | E13: 0
A14: Seguridad | B14: 50 | C14: 50 | D14: =(C14/B14) -> 1 | E14: =VLOOKUP(A14,Total!$A$4:$B$25,2,FALSE) -> 4
A15: Total | B15: =SUM(B2:B14) -> 821 | C15: =SUM(C2:C14) -> 809 | D15: =(C15/B15) -> 0.98538368 | E15: =SUM(E2:E14) -> 17

Sheet CatModulo
A1: Modulo | B1: Finanzas | C1: Fiscal | D1: Utilerias | E1: Prioridad | F1: Estado | G1: Responsable Dev | H1: Responsable QA | I1: Responsable UAT | J1: Impacto | K1: Probabilidad | L1: Tipo
A2: Finanzas | B2: Recepciones | C2: Facturación | D2: Catálogos | E2: Critico | F2: Pasó | G2: David Montes | H2: Marco Vezquez | I2: Nelva Flores | J2: Alto | K2: Alta | L2: BackEnd
A3: Fiscal | B3: Carta Porte | C3: Notas de crédito | D3: Gestión de seguridad | E3: Alta | F3: Falló | G3: Oscar Bonelli | H3: Saul Valdez | I3: Diana Hernandez | J3: Medio | K3: Media | L3: Batch
A4: Utilerias | B4: Recepciones MIGO | C4: Complemento de pago | D4: Auditoria | E4: Media | F4: En Progreso | G4: Fernando | H4: Paola Leon | I4: Liliana Preciado | J4: Bajo | K4: Baja | L4: FrontEnd
B5: Estado de cuenta | D5: Configuración de Parámetros | E5: Baja | F5: Pendiente | G5: Ricardo | H5: Ivan Cortes | L5: ETL
B6: Three way match | F6: Bloqueado | G6: Josue Lopez | H6: Alexis Gines
B7: Pagos | H7: Daniel Moreno
B8: Descuentos comerciales

Sheet Instrucciones
A1: 📋 GUÍA DE USO – MATRIZ DE SEGUIMIENTO DE PRUEBAS
A3: CAMPO | B3: DESCRIPCIÓN | C3: VALORES PERMITIDOS
A4: ID | B4: Identificador único del escenario. Formato: TC-XXX | C4: TC-001, TC-002…
A5: Escenario de Prueba | B5: Descripción clara y concisa del caso de prueba | C5: Texto libre
A6: Módulo | B6: Módulo principal del sistema al que pertenece | C6: Ej: Autenticación
A7: Submódulo | B7: Componente específico dentro del módulo | C7: Ej: Login, Logout
A8: Prioridad | B8: Nivel de criticidad del escenario | C8: Alta / Media / Baja
A9: Estado | B9: Estado actual de la ejecución del escenario | C9: Ver tabla de estados
A10: Resultado Esperado | B10: Comportamiento esperado según los criterios de aceptación | C10: Texto libre
A11: Resultado Obtenido | B11: Comportamiento real observado durante la ejecución | C11: Texto libre
A12: Vinculación Bug | B12: ID del bug en Jira si el escenario falló; '-' si no aplica | C12: STM-XXXX o -
A13: Responsable QA | B13: Nombre del QA asignado a este escenario | C13: Nombre del tester
A14: Responsable Negocio (UAT) | B14: Nombre del responsable del equipo de negocio | C14: Nombre Owner
A18: LEYENDA DE ESTADOS
A19: Pendiente | B19: El escenario aún no ha sido ejecutado
A20: En Progreso | B20: El escenario está siendo ejecutado
A21: Pasó | B21: El escenario fue ejecutado exitosamente
A22: Falló | B22: El resultado no coincidió con lo esperado
A23: Bloqueado | B23: No se puede ejecutar por un impedimento

Sheet Listado Issue Abiertos_v1.0
A1: Incidente | B1: Nivel | C1: Responsable | D1: Modulo | E1: Pantalla | F1: Revisión DEV | G1: Ajuste DEV | H1: Validado QA | I1: Comentario QA | J1: Fecha Reporte | K1: Fecha Resuelto
A2: En la pantalla de bitacora de actividades tiene el link de auditoria el cual no funciona, para este caso solo debe llevar a Inicio -> Herramientas y Utilerias -> Bitacora de Actividades | B2: Bajo | C2: Roberto | D2: Auditoria | E2: Bitacora de actividades | F2: x | G2: x | H2: x | I2: Validado por QA 23/06/2026 corregido.
A3: El diseño de la pantalla de Bitacora de actividades se distorsiono considerando el layout de todas las pantallas que se han trabajado | B3: Bajo | C3: Roberto | D3: Auditoria | E3: Bitacora de actividades | F3: x | G3: x | H3: x | I3: Validado por QA 23/06/2026 corregido.
A4: Cambiar el formato para descargar los reportes de Excel y CSV colocarlos en formato de botón secundario del lado izquierdo del botón de bloqueo de proveedores | B4: Bajo | C4: Ricardo | D4: Utilerias | E4: Bloqueo de proveedores | F4: x | G4: x | H4: x | I4: Validado por QA 23/06/2026 corregido.
A5: No permitir cargar la data solo hasta que el usuario seleccione los filtros de busqueda | B5: Bajo | C5: Roberto | D5: Utilerias | E5: Bloqueo de proveedores | F5: x | G5: x | H5: x | I5: Validado por QA 23/06/2026 corregido.
A6: El botón de buscar colocarlo al lado izquierdo del campo de busqueda Estatus y el link de limpar colocarlo a lado derecho del botón de buscar ademas de cambiarlo a botón secundarios | B6: Bajo | C6: Roberto | D6: Utilerias | E6: Bloqueo de proveedores | F6: x | G6: x | H6: x | I6: Validado por QA 23/06/2026 corregido.
A7: La pantalla de Catálogo de Catálogos no tiene el filtro de busqueda inicial presentando el grid de consulta y la distribución de los botones el botón de buscar colocarlo a la izquieda y el botón de limpiar a la derecha ademas de colocarlo en formato de botón | B7: Bajo | C7: Roberto | D7: Catálogo de catálogos | E7: Catálogo de catálogos | F7: x | G7: x | H7: x | I7: Validado por QA 23/06/2026 corregido.
A8: El link de volver en la pagina de catálogo de catálogos enviarlo a la derecha | B8: Bajo | C8: Roberto | D8: Utilerias | E8: Catálogo de catálogos | F8: x | G8: x | H8: x | I8: Validado por QA 23/06/2026 corregido.
A9: Los botones de Exportar a CSV y Excel dejarlos visible pero inactivos cuando no exista data, cuando retorne resultado el grid activar los botones | B9: Bajo | C9: Roberto | D9: Utilerias | E9: Catálogo de catálogos | F9: x | G9: x | H9: x | I9: Validado por QA 23/06/2026 corregido.
A10: Marca error de query al intentar agregar un nuevo evento en la pantalla "Catálogo de catálogo" | B10: Alto | C10: Ricardo | D10: Utilerias | E10: Catálogo de catálogos | F10: x | G10: x | H10: x | I10: Validado por QA 23/06/2026 corregido.
A11: Cambiar el formato para descargar los reportes de Excel y CSV colocarlos en formato de botón secundario del lado izquierdo del botón de catálogo de proveedores | B11: Bajo | C11: Roberto | D11: Utilerias | E11: Catálogo de proveedores | F11: x | G11: x | H11: x | I11: Validado por QA 23/06/2026 corregido.
A12: El botón de buscar colocarlo al lado izquierdo del campo de busqueda Estatus y el link de limpar colocarlo a lado derecho del botón de buscar ademas de cambiarlo a botón secundarios | B12: Bajo | C12: Roberto | D12: Utilerias | E12: Catálogo de proveedores | F12: x | G12: x | H12: x | I12: Validado por QA 23/06/2026 corregido.
A13: No permitir cargar la data solo hasta que el usuario seleccione los filtros de busqueda | B13: Bajo | C13: Roberto | D13: Utilerias | E13: Catálogo de proveedores | F13: x | G13: x | H13: x | I13: Validado por QA 23/06/2026 corregido.
... A15: Los Link del flujo de pantallas no funcionan en la pantalla y tampoco redirecciona al home Configuración de Parámetros | B15: Bajo | C15: Roberto | D15: Utilerias | E15: Configuración de parámetros | F15: x | G15: x | H15: x | I15: Validado por QA 23/06/2026 corregido.
A16: Agregar una columna en la addenda de la NC indicando si viene de un descuento comercial o ajuste por recepción 2 - Descuento Comercial | B16: Alto | C16: David | D16: Finanzas | E16: Descuentos Comercial | F16: x | G16: x | H16: x
A17: Cuando selecciona la opción de "Todos los tipos" en el listbox de "Tipo Rebate" no retorna nada, cuando se deja en blanco el tipo de rebate retorna resultado | B17: Medio | C17: Fernando | D17: Finanzas | E17: Descuentos Comercial | F17: x | G17: x | H17: x | I17: Validado por QA 23/06/2026 corregido.
A18: Cuando selecciona la opción de "Todos los tipos" en el listbox de estatus no retorna nada, cuando se deja en blanco el tipo de rebate retorna resultado | B18: Medio | C18: Fernando | D18: Finanzas | E18: Descuentos Comercial | F18: x | G18: x | H18: x | I18: Validado por QA 24/06/2026 corregido.
A19: El botón de buscar en el estado de cuenta se debe presentar como botón primario | B19: Bajo | C19: Oscar Bonelli | D19: Finanzas | E19: Estado de cuenta | F19: x | G19: x | H19: x | I19: Validado por QA 24/06/2026 corregido.
A20: La paginación en el estado de cuenta no esta funcionando | B20: Bajo | C20: Oscar Bonelli | D20: Finanzas | E20: Estado de cuenta | F20: x | G20: x | H20: x | I20: La paginación aplica hasta dar una segunda selección de los registros a visualizar
A21: En el grid de consulta el nombre del proveedor no se visualiza, considerando que se encuentra catálogado, el ejemplo es el proveedor 34786 | B21: Medio | C21: Fernando | D21: Finanzas | E21: Descuentos Comercial | F21: x | G21: x | H21: x | I21: Validado por QA 24/06/2026 corregido.
A22: Cuando se realiza la busqueda por proveedor, no retorna la información de los datos que estan relacionados | B22: Medio | C22: Fernando | D22: Finanzas | E22: Descuentos Comercial | F22: x | G22: x | H22: x | I22: Validado por QA 24/06/2026 corregido.
A23: El boton de limpiar no deja en blanco los parametros de busqueda | B23: Medio | C23: Fernando | D23: Finanzas | E23: Estado de cuenta | F23: x | G23: x | H23: x | I23: Validado por QA 25/06/2026 corregido.
A24: Cuando se busca un mes y no existe información, presentar una modal de alerta indicando que no existe información en el periodo consultado | B24: Medio | C24: Fernando | D24: Finanzas | E24: Estado de cuenta | F24: x | G24: x | H24: x | I24: Validado por QA 24/06/2026 corregido.
A25: No se visualiza el nombre del proveedor considerando que se encuentra dado de alta en el catálogo de proveedores | B25: Medio | C25: Fernando | D25: Finanzas | E25: Estado de cuenta | F25: x | G25: x | H25: x | I25: Validado por QA 24/06/2026 corregido.
A26: Marca error de consulta cuando seleccionamos el mes en el estado de cuenta | B26: Medio | C26: Fernando | D26: Finanzas | E26: Estado de cuenta | F26: x | G26: x | H26: x | I26: Validado por QA 25/06/2026 corregido.
A27: El calendario de busqueda en la pagina de facturación se pierde el mes y año en que se encuentra ademas es complejo operarlo | B27: Bajo | C27: Oscar Bonelli | D27: Fiscal | E27: Facturación | F27: x | G27: x | H27: x | I27: Validado por QA 25/06/2026 corregido.
A28: El tipo de proveedor no se visualiza en el grid de consulta de facturación cuando se hace un cambio en el catálogo de tipo de proveedores | B28: Medio | C28: David | D28: Fiscal | E28: Facturación | F28: x | G28: x | H28: x | I28: Validado por QA 25/06/2026 corregido.
... A30: El filtro de busqueda de las facturas esta retornando información de otros días de consulta | B30: Alto | C30: David | D30: Fiscal | E30: Facturación | F30: x | G30: x | H30: x | I30: Validado por QA 25/06/2026 corregido.
A31: No se visualiza el PDF publicado de la factura, marca error al intentar abrir el archivo | B31: Alto | C31: David | D31: Fiscal | E31: Facturación | F31: x | G31: x | H31: x
A32: Cuando se publica una factura la fecha de recepción esta considerando otro dato, lo que se espera es que se registre con la fecha actual del registro de la factura | B32: Alto | C32: David | D32: Fiscal | E32: Facturación | F32: x | G32: x | H32: x
A33: El botón de cancelar factura debera estar activo cuando se encuentre en los siguientes estatus: 3 - En proceso envio 6 - Error en el desglose de la factura 16 - Estructura invalida | B33: Alto | C33: Fernando | D33: Fiscal | E33: Facturación | F33: x | G33: x | H33: x | I33: Continua presentado los iconos para cancelar la factura
A34: Ajustar el texto principal de la tarjeta de finanzas por Operaciones -> Gestión de recepciones, pagos y descuentos | B34: Bajo | C34: Oscar Bonelli | D34: Finanzas | E34: Finanzas | F34: x | G34: x | H34: x | I34: Validado por QA 25/06/2026 corregido.
A35: Colocar en la parte superior de los grid de consulta el numero de registro que retorna la consulta en las siguientes pantallas Recepciones Guías de embarque Descuentos Comerciales Recepciones MIGO Estado de cuenta Three way match | B35: Bajo | C35: Oscar Bonelli | D35: Finanzas | E35: Finanzas | F35: x | G35: x | H35: x
A36: Ajustar el texto principal de la tarjeta de fiscal por Cuéntanos, ¿Qué necesitas? -> Gestión de documentación fiscal | B36: Bajo | C36: Oscar Bonelli | D36: Fiscal | E36: Fiscal | F36: x | G36: x | H36: x | I36: Validado por QA 25/06/2026 corregido.
A37: Colocar en la parte superior de los grid de consulta el numero de registro que retorna la consulta en las siguientes pantallas Facturacion Notas de Crédito Complemento pago | B37: Bajo | C37: Oscar Bonelli | D37: Fiscal | E37: Fiscal | F37: x | G37: x | H37: x
A38: El calendario de busqueda en la pagina de notas de crédito se pierde el mes y año en que se encuentra ademas es complejo operarlo | B38: Bajo | C38: Oscar Bonelli | D38: Fiscal | E38: Notas de crédito | F38: x | G38: x | H38: x | I38: Validado por QA 25/06/2026 corregido.
A39: En la pantalla de notas de crédito dejar un solo botón primario, el botón de Exportar CSV cambiarlo a blanco, | B39: Bajo | C39: Oscar Bonelli | D39: Fiscal | E39: Notas de crédito | F39: x | G39: x | H39: x | I39: Validado por QA 29/06/2026 corregido.
A40: El tipo de proveedor no se visualiza en el grid de consulta de notas de crédito cuando se hace un cambio en el catálogo de tipo de proveedores | B40: Medio | C40: David | D40: Fiscal | E40: Notas de crédito | F40: x | G40: x | H40: x
A41: El filtro de busqueda de las notas de crédito esta retornando información de otros días de consulta | B41: Alto | C41: David | D41: Fiscal | E41: Notas de crédito | F41: x | G41: x | H41: x
A42: Filtrar la condición de pago permitidas para dar de alta una nota de crédito | B42: Alto | C42: David | D42: Fiscal | E42: Notas de crédito | F42: x | G42: x | H42: x
...
